nohup: ignoring input
Writing results for L0C04CJ13.rsd.txt...
Traceback (most recent call last):
  File "/shared/why16gzl/conda/miniconda38/envs/EMNLP_env/lib/python3.7/site-packages/urllib3/connectionpool.py", line 672, in urlopen
    chunked=chunked,
  File "/shared/why16gzl/conda/miniconda38/envs/EMNLP_env/lib/python3.7/site-packages/urllib3/connectionpool.py", line 421, in _make_request
    six.raise_from(e, None)
  File "<string>", line 3, in raise_from
  File "/shared/why16gzl/conda/miniconda38/envs/EMNLP_env/lib/python3.7/site-packages/urllib3/connectionpool.py", line 416, in _make_request
    httplib_response = conn.getresponse()
  File "/shared/why16gzl/conda/miniconda38/envs/EMNLP_env/lib/python3.7/http/client.py", line 1344, in getresponse
    response.begin()
  File "/shared/why16gzl/conda/miniconda38/envs/EMNLP_env/lib/python3.7/http/client.py", line 306, in begin
    version, status, reason = self._read_status()
  File "/shared/why16gzl/conda/miniconda38/envs/EMNLP_env/lib/python3.7/http/client.py", line 275, in _read_status
    raise RemoteDisconnected("Remote end closed connection without"
http.client.RemoteDisconnected: Remote end closed connection without response

During handling of the above exception, another exception occurred:

Traceback (most recent call last):
  File "/shared/why16gzl/conda/miniconda38/envs/EMNLP_env/lib/python3.7/site-packages/requests/adapters.py", line 449, in send
    timeout=timeout
  File "/shared/why16gzl/conda/miniconda38/envs/EMNLP_env/lib/python3.7/site-packages/urllib3/connectionpool.py", line 720, in urlopen
    method, url, error=e, _pool=self, _stacktrace=sys.exc_info()[2]
  File "/shared/why16gzl/conda/miniconda38/envs/EMNLP_env/lib/python3.7/site-packages/urllib3/util/retry.py", line 400, in increment
    raise six.reraise(type(error), error, _stacktrace)
  File "/shared/why16gzl/conda/miniconda38/envs/EMNLP_env/lib/python3.7/site-packages/urllib3/packages/six.py", line 734, in reraise
    raise value.with_traceback(tb)
  File "/shared/why16gzl/conda/miniconda38/envs/EMNLP_env/lib/python3.7/site-packages/urllib3/connectionpool.py", line 672, in urlopen
    chunked=chunked,
  File "/shared/why16gzl/conda/miniconda38/envs/EMNLP_env/lib/python3.7/site-packages/urllib3/connectionpool.py", line 421, in _make_request
    six.raise_from(e, None)
  File "<string>", line 3, in raise_from
  File "/shared/why16gzl/conda/miniconda38/envs/EMNLP_env/lib/python3.7/site-packages/urllib3/connectionpool.py", line 416, in _make_request
    httplib_response = conn.getresponse()
  File "/shared/why16gzl/conda/miniconda38/envs/EMNLP_env/lib/python3.7/http/client.py", line 1344, in getresponse
    response.begin()
  File "/shared/why16gzl/conda/miniconda38/envs/EMNLP_env/lib/python3.7/http/client.py", line 306, in begin
    version, status, reason = self._read_status()
  File "/shared/why16gzl/conda/miniconda38/envs/EMNLP_env/lib/python3.7/http/client.py", line 275, in _read_status
    raise RemoteDisconnected("Remote end closed connection without"
urllib3.exceptions.ProtocolError: ('Connection aborted.', RemoteDisconnected('Remote end closed connection without response'))

During handling of the above exception, another exception occurred:

Traceback (most recent call last):
  File "ee_to_ta.py", line 143, in <module>
    fullTextDuration(ta, out_f)
  File "ee_to_ta.py", line 91, in fullTextDuration
    r = requests.post(url, data=payload, headers=headers)
  File "/shared/why16gzl/conda/miniconda38/envs/EMNLP_env/lib/python3.7/site-packages/requests/api.py", line 116, in post
    return request('post', url, data=data, json=json, **kwargs)
  File "/shared/why16gzl/conda/miniconda38/envs/EMNLP_env/lib/python3.7/site-packages/requests/api.py", line 60, in request
    return session.request(method=method, url=url, **kwargs)
  File "/shared/why16gzl/conda/miniconda38/envs/EMNLP_env/lib/python3.7/site-packages/requests/sessions.py", line 533, in request
    resp = self.send(prep, **send_kwargs)
  File "/shared/why16gzl/conda/miniconda38/envs/EMNLP_env/lib/python3.7/site-packages/requests/sessions.py", line 646, in send
    r = adapter.send(request, **kwargs)
  File "/shared/why16gzl/conda/miniconda38/envs/EMNLP_env/lib/python3.7/site-packages/requests/adapters.py", line 498, in send
    raise ConnectionError(err, request=request)
requests.exceptions.ConnectionError: ('Connection aborted.', RemoteDisconnected('Remote end closed connection without response'))
